Workbook

Sheet Mês a Mês
A1: Entradas | B1: Previstas | C1: Efetivadas | E1: Mês | F1: A pagar | G1: Previsão | H1: Pago | I1: Falta
A2: Salário | B2: 7297.86 | C2: 7297.86 | E2: =IFERROR(__xludf.DUMMYFUNCTION("QUERY(UNIQUE(FILTER(Controle!F2:F1000,Controle!F2:F1000<>"""",Controle!E2:E1000>=DATE(YEAR(EDATE(TODAY(),-1)),MONTH(EDATE(TODAY(),-1)),""01""))),""LIMIT 12"")"),"7/2026") -> 7/2026 | F2: =SUMIFS(Controle!G:G,Controle!F:F,CONCAT("=",$E2),Controle!H:H,"=0") -> 0 | G2: =$B$10-$F2 -> 8297.86 | H2: =SUMIFS(Controle!H:H,Controle!F:F,CONCAT("=",$E2),Controle!I:I,"<>") -> 13020.34 | I2: =IF(F2>H2,F2-H2,0) -> 0
A3: Comissão tia Noeli | B3: 1000 | C3: 210 | E3: =IFERROR(__xludf.DUMMYFUNCTION("""COMPUTED_VALUE"""),"8/2026") -> 8/2026 | F3: =SUMIFS(Controle!G:G,Controle!F:F,CONCAT("=",$E3),Controle!H:H,"=0") -> 0 | G3: =$B$10-$F3 -> 8297.86 | H3: =SUMIFS(Controle!H:H,Controle!F:F,CONCAT("=",$E3),Controle!I:I,"<>") -> 10578.62 | I3: =IF(F3>H3,F3-H3,0) -> 0
E4: =IFERROR(__xludf.DUMMYFUNCTION("""COMPUTED_VALUE"""),"9/2026") -> 9/2026 | F4: =SUMIFS(Controle!G:G,Controle!F:F,CONCAT("=",$E4),Controle!H:H,"=0") -> 9373.86 | G4: =$B$10-$F4 -> -1076 | H4: =SUMIFS(Controle!H:H,Controle!F:F,CONCAT("=",$E4),Controle!I:I,"<>") -> 3401.62 | I4: =IF(F4>H4,F4-H4,0) -> 5972.24
E5: =IFERROR(__xludf.DUMMYFUNCTION("""COMPUTED_VALUE"""),"10/2026") -> 10/2026 | F5: =SUMIFS(Controle!G:G,Controle!F:F,CONCAT("=",$E5),Controle!H:H,"=0") -> 4652.76 | G5: =$B$10-$F5 -> 3645.1 | H5: =SUMIFS(Controle!H:H,Controle!F:F,CONCAT("=",$E5),Controle!I:I,"<>") -> 3401.62 | I5: =IF(F5>H5,F5-H5,0) -> 1251.14
E6: =IFERROR(__xludf.DUMMYFUNCTION("""COMPUTED_VALUE"""),"11/2026") -> 11/2026 | F6: =SUMIFS(Controle!G:G,Controle!F:F,CONCAT("=",$E6),Controle!H:H,"=0") -> 5627.76 | G6: =$B$10-$F6 -> 2670.1 | H6: =SUMIFS(Controle!H:H,Controle!F:F,CONCAT("=",$E6),Controle!I:I,"<>") -> 901.22 | I6: =IF(F6>H6,F6-H6,0) -> 4726.54
E7: =IFERROR(__xludf.DUMMYFUNCTION("""COMPUTED_VALUE"""),"12/2026") -> 12/2026 | F7: =SUMIFS(Controle!G:G,Controle!F:F,CONCAT("=",$E7),Controle!H:H,"=0") -> 24812.58 | G7: =$B$10-$F7 -> -16514.72 | H7: =SUMIFS(Controle!H:H,Controle!F:F,CONCAT("=",$E7),Controle!I:I,"<>") -> 901.22 | I7: =IF(F7>H7,F7-H7,0) -> 23911.36
E8: =IFERROR(__xludf.DUMMYFUNCTION("""COMPUTED_VALUE"""),"1/2027") -> 1/2027 | F8: =SUMIFS(Controle!G:G,Controle!F:F,CONCAT("=",$E8),Controle!H:H,"=0") -> 4219.71 | G8: =$B$10-$F8 -> 4078.15 | H8: =SUMIFS(Controle!H:H,Controle!F:F,CONCAT("=",$E8),Controle!I:I,"<>") -> 901.22 | I8: =IF(F8>H8,F8-H8,0) -> 3318.49
E9: =IFERROR(__xludf.DUMMYFUNCTION("""COMPUTED_VALUE"""),"2/2027") -> 2/2027 | F9: =SUMIFS(Controle!G:G,Controle!F:F,CONCAT("=",$E9),Controle!H:H,"=0") -> 4219.71 | G9: =$B$10-$F9 -> 4078.15 | H9: =SUMIFS(Controle!H:H,Controle!F:F,CONCAT("=",$E9),Controle!I:I,"<>") -> 901.22 | I9: =IF(F9>H9,F9-H9,0) -> 3318.49
A10: Total | B10: =SUM(B2:B9) -> 8297.86 | C10: =SUM(C2:C9) -> 7507.86 | E10: =IFERROR(__xludf.DUMMYFUNCTION("""COMPUTED_VALUE"""),"3/2027") -> 3/2027 | F10: =SUMIFS(Controle!G:G,Controle!F:F,CONCAT("=",$E10),Controle!H:H,"=0") -> 4219.71 | G10: =$B$10-$F10 -> 4078.15 | H10: =SUMIFS(Controle!H:H,Controle!F:F,CONCAT("=",$E10),Controle!I:I,"<>") -> 901.22 | I10: =IF(F10>H10,F10-H10,0) -> 3318.49
E11: =IFERROR(__xludf.DUMMYFUNCTION("""COMPUTED_VALUE"""),"4/2027") -> 4/2027 | F11: =SUMIFS(Controle!G:G,Controle!F:F,CONCAT("=",$E11),Controle!H:H,"=0") -> 4219.71 | G11: =$B$10-$F11 -> 4078.15 | H11: =SUMIFS(Controle!H:H,Controle!F:F,CONCAT("=",$E11),Controle!I:I,"<>") -> 901.22 | I11: =IF(F11>H11,F11-H11,0) -> 3318.49
E12: =IFERROR(__xludf.DUMMYFUNCTION("""COMPUTED_VALUE"""),"5/2027") -> 5/2027 | F12: =SUMIFS(Controle!G:G,Controle!F:F,CONCAT("=",$E12),Controle!H:H,"=0") -> 4219.71 | G12: =$B$10-$F12 -> 4078.15 | H12: =SUMIFS(Controle!H:H,Controle!F:F,CONCAT("=",$E12),Controle!I:I,"<>") -> 901.22 | I12: =IF(F12>H12,F12-H12,0) -> 3318.49
E13: =IFERROR(__xludf.DUMMYFUNCTION("""COMPUTED_VALUE"""),"6/2027") -> 6/2027 | F13: =SUMIFS(Controle!G:G,Controle!F:F,CONCAT("=",$E13),Controle!H:H,"=0") -> 4219.71 | G13: =$B$10-$F13 -> 4078.15 | H13: =SUMIFS(Controle!H:H,Controle!F:F,CONCAT("=",$E13),Controle!I:I,"<>") -> 901.22 | I13: =IF(F13>H13,F13-H13,0) -> 3318.49
A16: 7000 | B16: 7073.23 | C16: =B16-A16 -> 73.23
A17: 2000000 | B17: =(A17*B16)/A16 -> 2020922.9 | C17: =B17-A17 -> 20922.857
B21: =B17/A17 -> 1.0104614 | C21: =B17*B21 -> 2042064.6 | D21: =C21-B17 -> 21141.74

Sheet Dashboard
A1: Mês | B1: 9/2026 | E1: Vencimento | F1: Link | G1: Contas | H1: Pago | I1: Á Pagar | J1: Total | L1: Mês | M1: A pagar | N1: Pago | O1: Falta | Q1: Credor | R1: Pago | S1: Devendo | T1: Total | V1: Fornecedor | W1: Pago | X1: Devendo | Y1: Total | AA1: Destino | AB1: Pago | AD1: Categorias | AE1: Pago
A2: Pago | B2: =SUMIFS(Controle!H:H,Controle!F:F,CONCAT("=",$B$1),Controle!I:I,"<>") -> 3401.62 | E2: =IFERROR(__xludf.DUMMYFUNCTION("SORT(UNIQUE(FILTER(Controle!E:E,Controle!F:F=$B$1)))"),46269.0) -> 46269 | F2: =HYPERLINK("https://docs.google.com/spreadsheets/d/1Uj96w5r3n0cneD7LaJDh3hKPtO69t6MtHFm4lkQ5K7I/edit?gid=775169775#gid=775169775&range=A"&MATCH(E2,Controle!E:E,0),"Ir") -> Ir | G2: =COUNTIF(Controle!E:E,CONCAT("=",E2)) -> 1 | H2: =SUMIFS(Controle!G:G,Controle!E:E,CONCAT("=",$E2),Controle!H:H,"<>0") -> 0 | I2: =SUMIFS(Controle!G:G,Controle!E:E,CONCAT("=",$E2),Controle!H:H,"=0") -> 1236.78 | J2: =SUMIFS(Controle!G:G,Controle!E:E,CONCAT("=",$E2)) -> 1236.78 | L2: =IFERROR(__xludf.DUMMYFUNCTION("QUERY(UNIQUE(FILTER(Controle!F2:F1009,Controle!F2:F1009<>"""",Controle!E2:E1009>=DATE(YEAR(EDATE(TODAY(),-1)),MONTH(EDATE(TODAY(),-1)),""01""))),""LIMIT 12"")"),"7/2026") -> 7/2026 | M2: =SUMIFS(Controle!G:G,Controle!F:F,CONCAT("=",$L2),Controle!H:H,"=0") -> 0 | N2: =SUMIFS(Controle!H:H,Controle!F:F,CONCAT("=",$L2),Controle!I:I,"<>") -> 13020.34 | O2: =IF(M2>N2,M2-N2,0) -> 0 | Q2: =IFERROR(__xludf.DUMMYFUNCTION("SORT(UNIQUE(FILTER(Controle!A:A,Controle!C:C=""Dívida"")))"),"Ademicon") -> Ademicon | R2: =SUMIFS(Controle!G:G,Controle!A:A,CONCAT("=",$Q2),Controle!H:H,"<>0") -> 44652 | S2: =SUMIFS(Controle!G:G,Controle!A:A,CONCAT("=",$Q2),Controle!H:H,"=0") -> 95810.05 | T2: =SUMIFS(Controle!G:G,Controle!A:A,CONCAT("=",$Q2)) -> 140462.05 | V2: =IFERROR(__xludf.DUMMYFUNCTION("UNIQUE(FILTER(Controle!A:A,Controle!C:C=""Fornecedor""))"),"Élio Squena - Tordilho Negro") -> Élio Squena - Tordilho Negro | W2: =SUMIFS(Controle!G:G,Controle!A:A,CONCAT("=",$V2),Controle!H:H,"<>0") -> 1717.87 | X2: =SUMIFS(Controle!G:G,Controle!A:A,CONCAT("=",$V2),Controle!H:H,"=0") -> 19976.48 | Y2: =SUMIFS(Controle!G:G,Controle!A:A,CONCAT("=",$V2)) -> 21694.35 | AA2: =IFERROR(__xludf.DUMMYFUNCTION("UNIQUE(FILTER(Controle!A2:A1009,Controle!C2:C1009<>""Fornecedor"",Controle!C2:C1009<>""Dívida""))"),"Copel") -> Copel | AB2: =SUMIFS(Controle!H:H,Controle!A:A,CONCAT("=",$AA2),Controle!I:I,"<>0") -> 7988.43 | AD2: {=SORT(UNIQUE(Categorias!A:A))} -> Água | AE2: =SUMIFS(Controle!H:H,Controle!D:D,CONCAT("=",$AD2),Controle!I:I,"<>0") -> 3835.4
A3: À Pagar | B3: =SUMIFS(Controle!G:G,Controle!F:F,CONCAT("=",$B$1),Controle!I:I,"=") -> 9373.86 | E3: =IFERROR(__xludf.DUMMYFUNCTION("""COMPUTED_VALUE"""),46272.0) -> 46272 | F3: =HYPERLINK("https://docs.google.com/spreadsheets/d/1Uj96w5r3n0cneD7LaJDh3hKPtO69t6MtHFm4lkQ5K7I/edit?gid=775169775#gid=775169775&range=A"&MATCH(E3,Controle!E:E,0),"Ir") -> Ir | G3: =COUNTIF(Controle!E:E,CONCAT("=",E3)) -> 1 | H3: =SUMIFS(Controle!G:G,Controle!E:E,CONCAT("=",$E3),Controle!H:H,"<>0") -> 1231.13 | I3: =SUMIFS(Controle!G:G,Controle!E:E,CONCAT("=",$E3),Controle!H:H,"=0") -> 0 | J3: =SUMIFS(Controle!G:G,Controle!E:E,CONCAT("=",$E3)) -> 1231.13 | L3: =IFERROR(__xludf.DUMMYFUNCTION("""COMPUTED_VALUE"""),"8/2026") -> 8/2026 | M3: =SUMIFS(Controle!G:G,Controle!F:F,CONCAT("=",$L3),Controle!H:H,"=0") -> 0 | N3: =SUMIFS(Controle!H:H,Controle!F:F,CONCAT("=",$L3),Controle!I:I,"<>") -> 10578.62 | O3: =IF(M3>N3,M3-N3,0) -> 0 | Q3: =IFERROR(__xludf.DUMMYFUNCTION("""COMPUTED_VALUE"""),"CC Cresol") -> CC Cresol | R3: =SUMIFS(Controle!G:G,Controle!A:A,CONCAT("=",$Q3),Controle!H:H,"<>0") -> 7469.5 | S3: =SUMIFS(Controle!G:G,Controle!A:A,CONCAT("=",$Q3),Controle!H:H,"=0") -> 0 | T3: =SUMIFS(Controle!G:G,Controle!A:A,CONCAT("=",$Q3)) -> 7469.5 | V3: =IFERROR(__xludf.DUMMYFUNCTION("""COMPUTED_VALUE"""),"Pampasul") -> Pampasul | W3: =SUMIFS(Controle!G:G,Controle!A:A,CONCAT("=",$V3),Controle!H:H,"<>0") -> 9005.58 | X3: =SUMIFS(Controle!G:G,Controle!A:A,CONCAT("=",$V3),Controle!H:H,"=0") -> 0 | Y3: =SUMIFS(Controle!G:G,Controle!A:A,CONCAT("=",$V3)) -> 9005.58 | AA3: =IFERROR(__xludf.DUMMYFUNCTION("""COMPUTED_VALUE"""),"Sanepar") -> Sanepar | AB3: =SUMIFS(Controle!H:H,Controle!A:A,CONCAT("=",$AA3),Controle!I:I,"<>0") -> 3835.4 | AD3: Categorias de conta | AE3: =SUMIFS(Controle!H:H,Controle!D:D,CONCAT("=",$AD3),Controle!I:I,"<>0") -> 0
A4: Vence hoje | B4: =SUMIFS(Controle!G:G,Controle!E:E,CONCATENATE("<=",DAY(NOW()),"/",MONTH(NOW()),"/",YEAR(NOW())),Controle!I:I,"=") -> 0 | E4: =IFERROR(__xludf.DUMMYFUNCTION("""COMPUTED_VALUE"""),46273.0) -> 46273 | F4: =HYPERLINK("https://docs.google.com/spreadsheets/d/1Uj96w5r3n0cneD7LaJDh3hKPtO69t6MtHFm4lkQ5K7I/edit?gid=775169775#gid=775169775&range=A"&MATCH(E4,Controle!E:E,0),"Ir") -> Ir | G4: =COUNTIF(Controle!E:E,CONCAT("=",E4)) -> 5 | H4: =SUMIFS(Controle!G:G,Controle!E:E,CONCAT("=",$E4),Controle!H:H,"<>0") -> 0 | I4: =SUMIFS(Controle!G:G,Controle!E:E,CONCAT("=",$E4),Controle!H:H,"=0") -> 7633.5 | J4: =SUMIFS(Controle!G:G,Controle!E:E,CONCAT("=",$E4)) -> 7633.5 | L4: =IFERROR(__xludf.DUMMYFUNCTION("""COMPUTED_VALUE"""),"9/2026") -> 9/2026 | M4: =SUMIFS(Controle!G:G,Controle!F:F,CONCAT("=",$L4),Controle!H:H,"=0") -> 9373.86 | N4: =SUMIFS(Controle!H:H,Controle!F:F,CONCAT("=",$L4),Controle!I:I,"<>") -> 3401.62 | O4: =IF(M4>N4,M4-N4,0) -> 5972.24 | Q4: =IFERROR(__xludf.DUMMYFUNCTION("""COMPUTED_VALUE"""),"CC Itaú") -> CC Itaú | R4: =SUMIFS(Controle!G:G,Controle!A:A,CONCAT("=",$Q4),Controle!H:H,"<>0") -> 25573.85 | S4: =SUMIFS(Controle!G:G,Controle!A:A,CONCAT("=",$Q4),Controle!H:H,"=0") -> 1068.8 | T4: =SUMIFS(Controle!G:G,Controle!A:A,CONCAT("=",$Q4)) -> 26642.65 | V4: =IFERROR(__xludf.DUMMYFUNCTION("""COMPUTED_VALUE"""),"Botinas") -> Botinas | W4: =SUMIFS(Controle!G:G,Controle!A:A,CONCAT("=",$V4),Controle!H:H,"<>0") -> 2000 | X4: =SUMIFS(Controle!G:G,Controle!A:A,CONCAT("=",$V4),Controle!H:H,"=0") -> 0 | Y4: =SUMIFS(Controle!G:G,Controle!A:A,CONCAT("=",$V4)) -> 2000 | AA4: =IFERROR(__xludf.DUMMYFUNCTION("""COMPUTED_VALUE"""),"Aluguel") -> Aluguel | AB4: =SUMIFS(Controle!H:H,Controle!A:A,CONCAT("=",$AA4),Controle!I:I,"<>0") -> 24022.6 | AD4: Combustivel | AE4: =SUMIFS(Controle!H:H,Controle!D:D,CONCAT("=",$AD4),Controle!I:I,"<>0") -> 100
E5: =IFERROR(__xludf.DUMMYFUNCTION("""COMPUTED_VALUE"""),46275.0) -> 46275 | F5: =HYPERLINK("https://docs.google.com/spreadsheets/d/1Uj96w5r3n0cneD7LaJDh3hKPtO69t6MtHFm4lkQ5K7I/edit?gid=775169775#gid=775169775&range=A"&MATCH(E5,Controle!E:E,0),"Ir") -> Ir | G5: =COUNTIF(Controle!E:E,CONCAT("=",E5)) -> 2 | H5: =SUMIFS(Controle!G:G,Controle!E:E,CONCAT("=",$E5),Controle!H:H,"<>0") -> 0 | I5: =SUMIFS(Controle!G:G,Controle!E:E,CONCAT("=",$E5),Controle!H:H,"=0") -> 334.48 | J5: =SUMIFS(Controle!G:G,Controle!E:E,CONCAT("=",$E5)) -> 334.48 | L5: =IFERROR(__xludf.DUMMYFUNCTION("""COMPUTED_VALUE"""),"10/2026") -> 10/2026 | M5: =SUMIFS(Controle!G:G,Controle!F:F,CONCAT("=",$L5),Controle!H:H,"=0") -> 4652.76 | N5: =SUMIFS(Controle!H:H,Controle!F:F,CONCAT("=",$L5),Controle!I:I,"<>") -> 3401.62 | O5: =IF(M5>N5,M5-N5,0) -> 1251.14 | Q5: =IFERROR(__xludf.DUMMYFUNCTION("""COMPUTED_VALUE"""),"CC Nubank") -> CC Nubank | R5: =SUMIFS(Controle!G:G,Controle!A:A,CONCAT("=",$Q5),Controle!H:H,"<>0") -> 48008.41 | S5: =SUMIFS(Controle!G:G,Controle!A:A,CONCAT("=",$Q5),Controle!H:H,"=0") -> 417.28 | T5: =SUMIFS(Controle!G:G,Controle!A:A,CONCAT("=",$Q5)) -> 48425.69 | V5: =IFERROR(__xludf.DUMMYFUNCTION("""COMPUTED_VALUE"""),"Qualitchê") -> Qualitchê | W5: =SUMIFS(Controle!G:G,Controle!A:A,CONCAT("=",$V5),Controle!H:H,"<>0") -> 2643.2 | X5: =SUMIFS(Controle!G:G,Controle!A:A,CONCAT("=",$V5),Controle!H:H,"=0") -> 0 | Y5: =SUMIFS(Controle!G:G,Controle!A:A,CONCAT("=",$V5)) -> 2643.2 | AA5: =IFERROR(__xludf.DUMMYFUNCTION("""COMPUTED_VALUE"""),"TIM") -> TIM | AB5: =SUMIFS(Controle!H:H,Controle!A:A,CONCAT("=",$AA5),Controle!I:I,"<>0") -> 1297.88 | AD5: Dívida | AE5: =SUMIFS(Controle!H:H,Controle!D:D,CONCAT("=",$AD5),Controle!I:I,"<>0") -> 145445.38
E6: =IFERROR(__xludf.DUMMYFUNCTION("""COMPUTED_VALUE"""),46285.0) -> 46285 | F6: =HYPERLINK("https://docs.google.com/spreadsheets/d/1Uj96w5r3n0cneD7LaJDh3hKPtO69t6MtHFm4lkQ5K7I/edit?gid=775169775#gid=775169775&range=A"&MATCH(E6,Controle!E:E,0),"Ir") -> Ir | G6: =COUNTIF(Controle!E:E,CONCAT("=",E6)) -> 2 | H6: =SUMIFS(Controle!G:G,Controle!E:E,CONCAT("=",$E6),Controle!H:H,"<>0") -> 0 | I6: =SUMIFS(Controle!G:G,Controle!E:E,CONCAT("=",$E6),Controle!H:H,"=0") -> 169.1 | J6: =SUMIFS(Controle!G:G,Controle!E:E,CONCAT("=",$E6)) -> 169.1 | L6: =IFERROR(__xludf.DUMMYFUNCTION("""COMPUTED_VALUE"""),"11/2026") -> 11/2026 | M6: =SUMIFS(Controle!G:G,Controle!F:F,CONCAT("=",$L6),Controle!H:H,"=0") -> 5627.76 | N6: =SUMIFS(Controle!H:H,Controle!F:F,CONCAT("=",$L6),Controle!I:I,"<>") -> 901.22 | O6: =IF(M6>N6,M6-N6,0) -> 4726.54 | Q6: =IFERROR(__xludf.DUMMYFUNCTION("""COMPUTED_VALUE"""),"CC Santander") -> CC Santander | R6: =SUMIFS(Controle!G:G,Controle!A:A,CONCAT("=",$Q6),Controle!H:H,"<>0") -> 227332.8 | S6: =SUMIFS(Controle!G:G,Controle!A:A,CONCAT("=",$Q6),Controle!H:H,"=0") -> 8384.95 | T6: =SUMIFS(Controle!G:G,Controle!A:A,CONCAT("=",$Q6)) -> 235717.75 | V6: =IFERROR(__xludf.DUMMYFUNCTION("""COMPUTED_VALUE"""),"Sokolowski") -> Sokolowski | W6: =SUMIFS(Controle!G:G,Controle!A:A,CONCAT("=",$V6),Controle!H:H,"<>0") -> 207.27 | X6: =SUMIFS(Controle!G:G,Controle!A:A,CONCAT("=",$V6),Controle!H:H,"=0") -> 0 | Y6: =SUMIFS(Controle!G:G,Controle!A:A,CONCAT("=",$V6)) -> 207.27 | AA6: =IFERROR(__xludf.DUMMYFUNCTION("""COMPUTED_VALUE"""),"Meganet") -> Meganet | AB6: =SUMIFS(Controle!H:H,Controle!A:A,CONCAT("=",$AA6),Controle!I:I,"<>0") -> 5994.9 | AD6: Imposto | AE6: =SUMIFS(Controle!H:H,Controle!D:D,CONCAT("=",$AD6),Controle!I:I,"<>0") -> 4125.9
A7: Local | B7: Valor | C7: Aplicação | E7: =IFERROR(__xludf.DUMMYFUNCTION("""COMPUTED_VALUE"""),46291.0) -> 46291 | F7: =HYPERLINK("https://docs.google.com/spreadsheets/d/1Uj96w5r3n0cneD7LaJDh3hKPtO69t6MtHFm4lkQ5K7I/edit?gid=775169775#gid=775169775&range=A"&MATCH(E7,Controle!E:E,0),"Ir") -> Ir | G7: =COUNTIF(Controle!E:E,CONCAT("=",E7)) -> 1 | H7: =SUMIFS(Controle!G:G,Controle!E:E,CONCAT("=",$E7),Controle!H:H,"<>0") -> 2500.4 | I7: =SUMIFS(Controle!G:G,Controle!E:E,CONCAT("=",$E7),Controle!H:H,"=0") -> 0 | J7: =SUMIFS(Controle!G:G,Controle!E:E,CONCAT("=",$E7)) -> 2500.4 | L7: =IFERROR(__xludf.DUMMYFUNCTION("""COMPUTED_VALUE"""),"12/2026") -> 12/2026 | M7: =SUMIFS(Controle!G:G,Controle!F:F,CONCAT("=",$L7),Controle!H:H,"=0") -> 24812.58 | N7: =SUMIFS(Controle!H:H,Controle!F:F,CONCAT("=",$L7),Controle!I:I,"<>") -> 901.22 | O7: =IF(M7>N7,M7-N7,0) -> 23911.36 | Q7: =IFERROR(__xludf.DUMMYFUNCTION("""COMPUTED_VALUE"""),"Empréstimo Consignado") -> Empréstimo Consignado | R7: =SUMIFS(Controle!G:G,Controle!A:A,CONCAT("=",$Q7),Controle!H:H,"<>0") -> 20003.2 | S7: =SUMIFS(Controle!G:G,Controle!A:A,CONCAT("=",$Q7),Controle!H:H,"=0") -> 160025.6 | T7: =SUMIFS(Controle!G:G,Controle!A:A,CONCAT("=",$Q7)) -> 180028.8 | V7: =IFERROR(__xludf.DUMMYFUNCTION("""COMPUTED_VALUE"""),"Ciarin") -> Ciarin | W7: =SUMIFS(Controle!G:G,Controle!A:A,CONCAT("=",$V7),Controle!H:H,"<>0") -> 551.08 | X7: =SUMIFS(Controle!G:G,Controle!A:A,CONCAT("=",$V7),Controle!H:H,"=0") -> 0 | Y7: =SUMIFS(Controle!G:G,Controle!A:A,CONCAT("=",$V7)) -> 551.08 | AA7: =IFERROR(__xludf.DUMMYFUNCTION("""COMPUTED_VALUE"""),"MEI") -> MEI | AB7: =SUMIFS(Controle!H:H,Controle!A:A,CONCAT("=",$AA7),Controle!I:I,"<>0") -> 4125.9 | AD7: Internet | AE7: =SUMIFS(Controle!H:H,Controle!D:D,CONCAT("=",$AD7),Controle!I:I,"<>0") -> 5994.9
A8: Santander | B8: =273.77+1005 -> 1278.77 | C8: 1385.73 | F8: =HYPERLINK("https://docs.google.com/spreadsheets/d/1Uj96w5r3n0cneD7LaJDh3hKPtO69t6MtHFm4lkQ5K7I/edit?gid=775169775#gid=775169775&range=A"&MATCH(E8,Controle!E:E,0),"Ir") -> #N/A | G8: =COUNTIF(Controle!E:E,CONCAT("=",E8)) -> 1214 | H8: =SUMIFS(Controle!G:G,Controle!E:E,CONCAT("=",$E8),Controle!H:H,"<>0") -> 0 | I8: =SUMIFS(Controle!G:G,Controle!E:E,CONCAT("=",$E8),Controle!H:H,"=0") -> 0 | J8: =SUMIFS(Controle!G:G,Controle!E:E,CONCAT("=",$E8)) -> 0 | L8: =IFERROR(__xludf.DUMMYFUNCTION("""COMPUTED_VALUE"""),"1/2027") -> 1/2027 | M8: =SUMIFS(Controle!G:G,Controle!F:F,CONCAT("=",$L8),Controle!H:H,"=0") -> 4219.71 | N8: =SUMIFS(Controle!H:H,Controle!F:F,CONCAT("=",$L8),Controle!I:I,"<>") -> 901.22 | O8: =IF(M8>N8,M8-N8,0) -> 3318.49 | Q8: =IFERROR(__xludf.DUMMYFUNCTION("""COMPUTED_VALUE"""),"Empréstimo Cresol") -> Empréstimo Cresol | R8: =SUMIFS(Controle!G:G,Controle!A:A,CONCAT("=",$Q8),Controle!H:H,"<>0") -> 24376.02 | S8: =SUMIFS(Controle!G:G,Controle!A:A,CONCAT("=",$Q8),Controle!H:H,"=0") -> 0 | T8: =SUMIFS(Controle!G:G,Controle!A:A,CONCAT("=",$Q8)) -> 24376.02 | V8: =IFERROR(__xludf.DUMMYFUNCTION("""COMPUTED_VALUE"""),"MOR") -> MOR | W8: =SUMIFS(Controle!G:G,Controle!A:A,CONCAT("=",$V8),Controle!H:H,"<>0") -> 1348.33 | X8: =SUMIFS(Controle!G:G,Controle!A:A,CONCAT("=",$V8),Controle!H:H,"=0") -> 0 | Y8: =SUMIFS(Controle!G:G,Controle!A:A,CONCAT("=",$V8)) -> 1348.33 | AA8: =IFERROR(__xludf.DUMMYFUNCTION("""COMPUTED_VALUE"""),"Seguro Kwid") -> Seguro Kwid | AB8: =SUMIFS(Controle!H:H,Controle!A:A,CONCAT("=",$AA8),Controle!I:I,"<>0") -> 1715.8 | AD8: Investimento | AE8: =SUMIFS(Controle!H:H,Controle!D:D,CONCAT("=",$AD8),Controle!I:I,"<>0") -> 368231.99
A9: Cresol | B9: =0 -> 0 | F9: =HYPERLINK("https://docs.google.com/spreadsheets/d/1Uj96w5r3n0cneD7LaJDh3hKPtO69t6MtHFm4lkQ5K7I/edit?gid=775169775#gid=775169775&range=A"&MATCH(E9,Controle!E:E,0),"Ir") -> #N/A | G9: =COUNTIF(Controle!E:E,CONCAT("=",E9)) -> 1214 | H9: =SUMIFS(Controle!G:G,Controle!E:E,CONCAT("=",$E9),Controle!H:H,"<>0") -> 0 | I9: =SUMIFS(Controle!G:G,Controle!E:E,CONCAT("=",$E9),Controle!H:H,"=0") -> 0 | J9: =SUMIFS(Controle!G:G,Controle!E:E,CONCAT("=",$E9)) -> 0 | L9: =IFERROR(__xludf.DUMMYFUNCTION("""COMPUTED_VALUE"""),"2/2027") -> 2/2027 | M9: =SUMIFS(Controle!G:G,Controle!F:F,CONCAT("=",$L9),Controle!H:H,"=0") -> 4219.71 | N9: =SUMIFS(Controle!H:H,Controle!F:F,CONCAT("=",$L9),Controle!I:I,"<>") -> 901.22 | O9: =IF(M9>N9,M9-N9,0) -> 3318.49 | Q9: =IFERROR(__xludf.DUMMYFUNCTION("""COMPUTED_VALUE"""),"Empréstimo Nubank") -> Empréstimo Nubank | R9: =SUMIFS(Controle!G:G,Controle!A:A,CONCAT("=",$Q9),Controle!H:H,"<>0") -> 20385.44 | S9: =SUMIFS(Controle!G:G,Controle!A:A,CONCAT("=",$Q9),Controle!H:H,"=0") -> 0 | T9: =SUMIFS(Controle!G:G,Controle!A:A,CONCAT("=",$Q9)) -> 20385.44 | V9: =IFERROR(__xludf.DUMMYFUNCTION("""COMPUTED_VALUE"""),"Black Erva") -> Black Erva | W9: =SUMIFS(Controle!G:G,Controle!A:A,CONCAT("=",$V9),Controle!H:H,"<>0") -> 3681.78 | X9: =SUMIFS(Controle!G:G,Controle!A:A,CONCAT("=",$V9),Controle!H:H,"=0") -> 0 | Y9: =SUMIFS(Controle!G:G,Controle!A:A,CONCAT("=",$V9)) -> 3681.78 | AA9: =IFERROR(__xludf.DUMMYFUNCTION("""COMPUTED_VALUE"""),"NAY Carro de Som") -> NAY Carro de Som | AB9: =SUMIFS(Controle!H:H,Controle!A:A,CONCAT("=",$AA9),Controle!I:I,"<>0") -> 100 | AD9: Locação | AE9: =SUMIFS(Controle!H:H,Controle!D:D,CONCAT("=",$AD9),Controle!I:I,"<>0") -> 24022.6
A10: Infinite Pay | B10: 0 | F10: =HYPERLINK("https://docs.google.com/spreadsheets/d/1Uj96w5r3n0cneD7LaJDh3hKPtO69t6MtHFm4lkQ5K7I/edit?gid=775169775#gid=775169775&range=A"&MATCH(E10,Controle!E:E,0),"Ir") -> #N/A | G10: =COUNTIF(Controle!E:E,CONCAT("=",E10)) -> 1214 | H10: =SUMIFS(Controle!G:G,Controle!E:E,CONCAT("=",$E10),Controle!H:H,"<>0") -> 0 | I10: =SUMIFS(Controle!G:G,Controle!E:E,CONCAT("=",$E10),Controle!H:H,"=0") -> 0 | J10: =SUMIFS(Controle!G:G,Controle!E:E,CONCAT("=",$E10)) -> 0 | L10: =IFERROR(__xludf.DUMMYFUNCTION("""COMPUTED_VALUE"""),"3/2027") -> 3/2027 | M10: =SUMIFS(Controle!G:G,Controle!F:F,CONCAT("=",$L10),Controle!H:H,"=0") -> 4219.71 | N10: =SUMIFS(Controle!H:H,Controle!F:F,CONCAT("=",$L10),Controle!I:I,"<>") -> 901.22 | O10: =IF(M10>N10,M10-N10,0) -> 3318.49 | Q10: =IFERROR(__xludf.DUMMYFUNCTION("""COMPUTED_VALUE"""),"Financiamento Creditas") -> Financiamento Creditas | R10: =SUMIFS(Controle!G:G,Controle!A:A,CONCAT("=",$Q10),Controle!H:H,"<>0") -> 59089.6 | S10: =SUMIFS(Controle!G:G,Controle!A:A,CONCAT("=",$Q10),Controle!H:H,"=0") -> 0 | T10: =SUMIFS(Controle!G:G,Controle!A:A,CONCAT("=",$Q10)) -> 59089.6 | V10: =IFERROR(__xludf.DUMMYFUNCTION("""COMPUTED_VALUE"""),"Mazutti") -> Mazutti | W10: =SUMIFS(Controle!G:G,Controle!A:A,CONCAT("=",$V10),Controle!H:H,"<>0") -> 720 | X10: =SUMIFS(Controle!G:G,Controle!A:A,CONCAT("=",$V10),Controle!H:H,"=0") -> 0 | Y10: =SUMIFS(Controle!G:G,Controle!A:A,CONCAT("=",$V10)) -> 720 | AA10: =IFERROR(__xludf.DUMMYFUNCTION("""COMPUTED_VALUE"""),"Mercado São José") -> Mercado São José | AB10: =SUMIFS(Controle!H:H,Controle!A:A,CONCAT("=",$AA10),Controle!I:I,"<>0") -> 67.64 | AD10: Luz | AE10: =SUMIFS(Controle!H:H,Controle!D:D,CONCAT("=",$AD10),Controle!I:I,"<>0") -> 7988.43
A11: Itaú | B11: =5088.84+(5088.84*0.041) -> 5297.4824 | C11: 0 | F11: =HYPERLINK("https://docs.google.com/spreadsheets/d/1Uj96w5r3n0cneD7LaJDh3hKPtO69t6MtHFm4lkQ5K7I/edit?gid=775169775#gid=775169775&range=A"&MATCH(E11,Controle!E:E,0),"Ir") -> #N/A | G11: =COUNTIF(Controle!E:E,CONCAT("=",E11)) -> 1214 | H11: =SUMIFS(Controle!G:G,Controle!E:E,CONCAT("=",$E11),Controle!H:H,"<>0") -> 0 | I11: =SUMIFS(Controle!G:G,Controle!E:E,CONCAT("=",$E11),Controle!H:H,"=0") -> 0 | J11: =SUMIFS(Controle!G:G,Controle!E:E,CONCAT("=",$E11)) -> 0 | L11: =IFERROR(__xludf.DUMMYFUNCTION("""COMPUTED_VALUE"""),"4/2027") -> 4/2027 | M11: =SUMIFS(Controle!G:G,Controle!F:F,CONCAT("=",$L11),Controle!H:H,"=0") -> 4219.71 | N11: =SUMIFS(Controle!H:H,Controle!F:F,CONCAT("=",$L11),Controle!I:I,"<>") -> 901.22 | O11: =IF(M11>N11,M11-N11,0) -> 3318.49 | Q11: =IFERROR(__xludf.DUMMYFUNCTION("""COMPUTED_VALUE"""),"Financiamento Santander") -> Financiamento Santander | R11: =SUMIFS(Controle!G:G,Controle!A:A,CONCAT("=",$Q11),Controle!H:H,"<>0") -> 751.83 | S11: =SUMIFS(Controle!G:G,Controle!A:A,CONCAT("=",$Q11),Controle!H:H,"=0") -> 0 | T11: =SUMIFS(Controle!G:G,Controle!A:A,CONCAT("=",$Q11)) -> 751.83 | V11: =IFERROR(__xludf.DUMMYFUNCTION("""COMPUTED_VALUE"""),"Pé na Estrada") -> Pé na Estrada | W11: =SUMIFS(Controle!G:G,Controle!A:A,CONCAT("=",$V11),Controle!H:H,"<>0") -> 8692 | X11: =SUMIFS(Controle!G:G,Controle!A:A,CONCAT("=",$V11),Controle!H:H,"=0") -> 0 | Y11: =SUMIFS(Controle!G:G,Controle!A:A,CONCAT("=",$V11)) -> 8692 | AA11: =IFERROR(__xludf.DUMMYFUNCTION("""COMPUTED_VALUE"""),"Mercado Bom Preço") -> Mercado Bom Preço | AB11: =SUMIFS(Controle!H:H,Controle!A:A,CONCAT("=",$AA11),Controle!I:I,"<>0") -> 74.24 | AD11: Mercado | AE11: =SUMIFS(Controle!H:H,Controle!D:D,CONCAT("=",$AD11),Controle!I:I,"<>0") -> 571.85
A12: Nubank | B12: 0 | F12: =HYPERLINK("https://docs.google.com/spreadsheets/d/1Uj96w5r3n0cneD7LaJDh3hKPtO69t6MtHFm4lkQ5K7I/edit?gid=775169775#gid=775169775&range=A"&MATCH(E12,Controle!E:E,0),"Ir") -> #N/A | G12: =COUNTIF(Controle!E:E,CONCAT("=",E12)) -> 1214 | H12: =SUMIFS(Controle!G:G,Controle!E:E,CONCAT("=",$E12),Controle!H:H,"<>0") -> 0 | I12: =SUMIFS(Controle!G:G,Controle!E:E,CONCAT("=",$E12),Controle!H:H,"=0") -> 0 | J12: =SUMIFS(Controle!G:G,Controle!E:E,CONCAT("=",$E12)) -> 0 | L12: =IFERROR(__xludf.DUMMYFUNCTION("""COMPUTED_VALUE"""),"5/2027") -> 5/2027 | M12: =SUMIFS(Controle!G:G,Controle!F:F,CONCAT("=",$L12),Controle!H:H,"=0") -> 4219.71 | N12: =SUMIFS(Controle!H:H,Controle!F:F,CONCAT("=",$L12),Controle!I:I,"<>") -> 901.22 | O12: =IF(M12>N12,M12-N12,0) -> 3318.49 | Q12: =IFERROR(__xludf.DUMMYFUNCTION("""COMPUTED_VALUE"""),"Financiamento Tucson") -> Financiamento Tucson | R12: =SUMIFS(Controle!G:G,Controle!A:A,CONCAT("=",$Q12),Controle!H:H,"<>0") -> 2473.56 | S12: =SUMIFS(Controle!G:G,Controle!A:A,CONCAT("=",$Q12),Controle!H:H,"=0") -> 1236.78 | T12: =SUMIFS(Controle!G:G,Controle!A:A,CONCAT("=",$Q12)) -> 3710.34 | V12: =IFERROR(__xludf.DUMMYFUNCTION("""COMPUTED_VALUE"""),"C. F. Menezes & Carvalho Ltda - Qualitche") -> C. F. Menezes & Carvalho Ltda - Qualitche | W12: =SUMIFS(Controle!G:G,Controle!A:A,CONCAT("=",$V12),Controle!H:H,"<>0") -> 1840 | X12: =SUMIFS(Controle!G:G,Controle!A:A,CONCAT("=",$V12),Controle!H:H,"=0") -> 0 | Y12: =SUMIFS(Controle!G:G,Controle!A:A,CONCAT("=",$V12)) -> 1840 | AA12: =IFERROR(__xludf.DUMMYFUNCTION("""COMPUTED_VALUE"""),"Posto Fox") -> Posto Fox | AB12: =SUMIFS(Controle!H:H,Controle!A:A,CONCAT("=",$AA12),Controle!I:I,"<>0") -> 100 | AD12: Seguro | AE12: =SUMIFS(Controle!H:H,Controle!D:D,CONCAT("=",$AD12),Controle!I:I,"<>0") -> 1715.8
A13: CEF | B13: 0 | F13: =HYPERLINK("https://docs.google.com/spreadsheets/d/1Uj96w5r3n0cneD7LaJDh3hKPtO69t6MtHFm4lkQ5K7I/edit?gid=775169775#gid=775169775&range=A"&MATCH(E13,Controle!E:E,0),"Ir") -> #N/A | G13: =COUNTIF(Controle!E:E,CONCAT("=",E13)) -> 1214 | H13: =SUMIFS(Controle!G:G,Controle!E:E,CONCAT("=",$E13),Controle!H:H,"<>0") -> 0 | I13: =SUMIFS(Controle!G:G,Controle!E:E,CONCAT("=",$E13),Controle!H:H,"=0") -> 0 | J13: =SUMIFS(Controle!G:G,Controle!E:E,CONCAT("=",$E13)) -> 0 | L13: =IFERROR(__xludf.DUMMYFUNCTION("""COMPUTED_VALUE"""),"6/2027") -> 6/2027 | M13: =SUMIFS(Controle!G:G,Controle!F:F,CONCAT("=",$L13),Controle!H:H,"=0") -> 4219.71 | N13: =SUMIFS(Controle!H:H,Controle!F:F,CONCAT("=",$L13),Controle!I:I,"<>") -> 901.22 | O13: =IF(M13>N13,M13-N13,0) -> 3318.49 | R13: =SUMIFS(Controle!G:G,Controle!A:A,CONCAT("=",$Q13),Controle!H:H,"<>0") -> 0 | S13: =SUMIFS(Controle!G:G,Controle!A:A,CONCAT("=",$Q13),Controle!H:H,"=0") -> 0 | T13: =SUMIFS(Controle!G:G,Controle!A:A,CONCAT("=",$Q13)) -> 0 | V13: =IFERROR(__xludf.DUMMYFUNCTION("""COMPUTED_VALUE"""),"Calçados para Dança - Vuollo") -> Calçados para Dança - Vuollo | W13: =SUMIFS(Controle!G:G,Controle!A:A,CONCAT("=",$V13),Controle!H:H,"<>0") -> 3318 | X13: =SUMIFS(Controle!G:G,Controle!A:A,CONCAT("=",$V13),Controle!H:H,"=0") -> 0 | Y13: =SUMIFS(Controle!G:G,Controle!A:A,CONCAT("=",$V13)) -> 3318 | AA13: =IFERROR(__xludf.DUMMYFUNCTION("""COMPUTED_VALUE"""),"Mercado D'amille") -> Mercado D'amille | AB13: =SUMIFS(Controle!H:H,Controle!A:A,CONCAT("=",$AA13),Controle!I:I,"<>0") -> 340.07 | AD13: Selecione | AE13: =SUMIFS(Controle!H:H,Controle!D:D,CONCAT("=",$AD13),Controle!I:I,"<>0") -> 2473.56
A14: Carteira | B14: 0 | F14: =HYPERLINK("https://docs.google.com/spreadsheets/d/1Uj96w5r3n0cneD7LaJDh3hKPtO69t6MtHFm4lkQ5K7I/edit?gid=775169775#gid=775169775&range=A"&MATCH(E14,Controle!E:E,0),"Ir") -> #N/A | G14: =COUNTIF(Controle!E:E,CONCAT("=",E14)) -> 1214 | H14: =SUMIFS(Controle!G:G,Controle!E:E,CONCAT("=",$E14),Controle!H:H,"<>0") -> 0 | I14: =SUMIFS(Controle!G:G,Controle!E:E,CONCAT("=",$E14),Controle!H:H,"=0") -> 0 | J14: =SUMIFS(Controle!G:G,Controle!E:E,CONCAT("=",$E14)) -> 0 | R14: =SUMIFS(Controle!G:G,Controle!A:A,CONCAT("=",$Q14),Controle!H:H,"<>0") -> 0 | S14: =SUMIFS(Controle!G:G,Controle!A:A,CONCAT("=",$Q14),Controle!H:H,"=0") -> 0 | T14: =SUMIFS(Controle!G:G,Controle!A:A,CONCAT("=",$Q14)) -> 0 | V14: =IFERROR(__xludf.DUMMYFUNCTION("""COMPUTED_VALUE"""),"Montana") -> Montana | W14: =SUMIFS(Controle!G:G,Controle!A:A,CONCAT("=",$V14),Controle!H:H,"<>0") -> 2102.75 | X14: =SUMIFS(Controle!G:G,Controle!A:A,CONCAT("=",$V14),Controle!H:H,"=0") -> 0 | Y14: =SUMIFS(Controle!G:G,Controle!A:A,CONCAT("=",$V14)) -> 2102.75 | AA14: =IFERROR(__xludf.DUMMYFUNCTION("""COMPUTED_VALUE"""),"Tênis Cruz Machado") -> Tênis Cruz Machado | AB14: =SUMIFS(Controle!H:H,Controle!A:A,CONCAT("=",$AA14),Controle!I:I,"<>0") -> 89.9 | AD14: Telefonia | AE14: =SUMIFS(Controle!H:H,Controle!D:D,CONCAT("=",$AD14),Controle!I:I,"<>0") -> 1297.88
A15: Caixa | B15: 0 | F15: =HYPERLINK("https://docs.google.com/spreadsheets/d/1Uj96w5r3n0cneD7LaJDh3hKPtO69t6MtHFm4lkQ5K7I/edit?gid=775169775#gid=775169775&range=A"&MATCH(E15,Controle!E:E,0),"Ir") -> #N/A | G15: =COUNTIF(Controle!E:E,CONCAT("=",E15)) -> 1214 | H15: =SUMIFS(Controle!G:G,Controle!E:E,CONCAT("=",$E15),Controle!H:H,"<>0") -> 0 | I15: =SUMIFS(Controle!G:G,Controle!E:E,CONCAT("=",$E15),Controle!H:H,"=0") -> 0 | J15: =SUMIFS(Controle!G:G,Controle!E:E,CONCAT("=",$E15)) -> 0 | R15: =SUMIFS(Controle!G:G,Controle!A:A,CONCAT("=",$Q15),Controle!H:H,"<>0") -> 0 | S15: =SUMIFS(Controle!G:G,Controle!A:A,CONCAT("=",$Q15),Controle!H:H,"=0") -> 0 | T15: =SUMIFS(Controle!G:G,Controle!A:A,CONCAT("=",$Q15)) -> 0 | V15: =IFERROR(__xludf.DUMMYFUNCTION("""COMPUTED_VALUE"""),"E R Confecções - Chapéu Gaucho") -> E R Confecções - Chapéu Gaucho | W15: =SUMIFS(Controle!G:G,Controle!A:A,CONCAT("=",$V15),Controle!H:H,"<>0") -> 758.78 | X15: =SUMIFS(Controle!G:G,Controle!A:A,CONCAT("=",$V15),Controle!H:H,"=0") -> 0 | Y15: =SUMIFS(Controle!G:G,Controle!A:A,CONCAT("=",$V15)) -> 758.78 | AA15: =IFERROR(__xludf.DUMMYFUNCTION("""COMPUTED_VALUE"""),"Pampasul") -> Pampasul | AB15: =SUMIFS(Controle!H:H,Controle!A:A,CONCAT("=",$AA15),Controle!I:I,"<>0") -> 9005.58 | AE15: =SUMIFS(Controle!H:H,Controle!D:D,CONCAT("=",$AD15),Controle!I:I,"<>0") -> 0
A16: Caju | B16: 396.37 | F16: =HYPERLINK("https://docs.google.com/spreadsheets/d/1Uj96w5r3n0cneD7LaJDh3hKPtO69t6MtHFm4lkQ5K7I/edit?gid=775169775#gid=775169775&range=A"&MATCH(E16,Controle!E:E,0),"Ir") -> #N/A | G16: =COUNTIF(Controle!E:E,CONCAT("=",E16)) -> 1214 | H16: =SUMIFS(Controle!G:G,Controle!E:E,CONCAT("=",$E16),Controle!H:H,"<>0") -> 0 | I16: =SUMIFS(Controle!G:G,Controle!E:E,CONCAT("=",$E16),Controle!H:H,"=0") -> 0 | J16: =SUMIFS(Controle!G:G,Controle!E:E,CONCAT("=",$E16)) -> 0 | R16: =SUMIFS(Controle!G:G,Controle!A:A,CONCAT("=",$Q16),Controle!H:H,"<>0") -> 0 | S16: =SUMIFS(Controle!G:G,Controle!A:A,CONCAT("=",$Q16),Controle!H:H,"=0") -> 0 | T16: =SUMIFS(Controle!G:G,Controle!A:A,CONCAT("=",$Q16)) -> 0 | V16: =IFERROR(__xludf.DUMMYFUNCTION("""COMPUTED_VALUE"""),"Pura Raça") -> Pura Raça | W16: =SUMIFS(Controle!G:G,Controle!A:A,CONCAT("=",$V16),Controle!H:H,"<>0") -> 5885.97 | X16: =SUMIFS(Controle!G:G,Controle!A:A,CONCAT("=",$V16),Controle!H:H,"=0") -> 0 | Y16: =SUMIFS(Controle!G:G,Controle!A:A,CONCAT("=",$V16)) -> 5885.97 | AE16: =SUMIFS(Controle!H:H,Controle!D:D,CONCAT("=",$AD16),Controle!I:I,"<>0") -> 0
F17: =HYPERLINK("https://docs.google.com/spreadsheets/d/1Uj96w5r3n0cneD7LaJDh3hKPtO69t6MtHFm4lkQ5K7I/edit?gid=775169775#gid=775169775&range=A"&MATCH(E17,Controle!E:E,0),"Ir") -> #N/A | G17: =COUNTIF(Controle!E:E,CONCAT("=",E17)) -> 1214 | H17: =SUMIFS(Controle!G:G,Controle!E:E,CONCAT("=",$E17),Controle!H:H,"<>0") -> 0 | I17: =SUMIFS(Controle!G:G,Controle!E:E,CONCAT("=",$E17),Controle!H:H,"=0") -> 0 | J17: =SUMIFS(Controle!G:G,Controle!E:E,CONCAT("=",$E17)) -> 0 | R17: =SUMIFS(Controle!G:G,Controle!A:A,CONCAT("=",$Q17),Controle!H:H,"<>0") -> 0 | S17: =SUMIFS(Controle!G:G,Controle!A:A,CONCAT("=",$Q17),Controle!H:H,"=0") -> 0 | T17: =SUMIFS(Controle!G:G,Controle!A:A,CONCAT("=",$Q17)) -> 0 | V17: =IFERROR(__xludf.DUMMYFUNCTION("""COMPUTED_VALUE"""),"Black") -> Black | W17: =SUMIFS(Controle!G:G,Controle!A:A,CONCAT("=",$V17),Controle!H:H,"<>0") -> 541.2 | X17: =SUMIFS(Controle!G:G,Controle!A:A,CONCAT("=",$V17),Controle!H:H,"=0") -> 0 | Y17: =SUMIFS(Controle!G:G,Controle!A:A,CONCAT("=",$V17)) -> 541.2 | AE17: =SUMIFS(Controle!H:H,Controle!D:D,CONCAT("=",$AD17),Controle!I:I,"<>0") -> 0
A18: Total | B18: =SUM(B8:B17) -> 6972.6224 | F18: =HYPERLINK("https://docs.google.com/spreadsheets/d/1Uj96w5r3n0cneD7LaJDh3hKPtO69t6MtHFm4lkQ5K7I/edit?gid=775169775#gid=775169775&range=A"&MATCH(E18,Controle!E:E,0),"Ir") -> #N/A | G18: =COUNTIF(Controle!E:E,CONCAT("=",E18)) -> 1214 | H18: =SUMIFS(Controle!G:G,Controle!E:E,CONCAT("=",$E18),Controle!H:H,"<>0") -> 0 | I18: =SUMIFS(Controle!G:G,Controle!E:E,CONCAT("=",$E18),Controle!H:H,"=0") -> 0 | J18: =SUMIFS(Controle!G:G,Controle!E:E,CONCAT("=",$E18)) -> 0 | R18: =SUMIFS(Controle!G:G,Controle!A:A,CONCAT("=",$Q18),Controle!H:H,"<>0") -> 0 | S18: =SUMIFS(Controle!G:G,Controle!A:A,CONCAT("=",$Q18),Controle!H:H,"=0") -> 0 | T18: =SUMIFS(Controle!G:G,Controle!A:A,CONCAT("=",$Q18)) -> 0 | W18: =SUMIFS(Controle!G:G,Controle!A:A,CONCAT("=",$V18),Controle!H:H,"<>0") -> 0 | X18: =SUMIFS(Controle!G:G,Controle!A:A,CONCAT("=",$V18),Controle!H:H,"=0") -> 0 | Y18: =SUMIFS(Controle!G:G,Controle!A:A,CONCAT("=",$V18)) -> 0 | AE18: =SUMIFS(Controle!H:H,Controle!D:D,CONCAT("=",$AD18),Controle!I:I,"<>0") -> 0
A19: Diferenca | B19: =B18-B3 -> -2401.2376 | C19: =SUM(C8:C18)+B19 -> -1015.5076 | F19: =HYPERLINK("https://docs.google.com/spreadsheets/d/1Uj96w5r3n0cneD7LaJDh3hKPtO69t6MtHFm4lkQ5K7I/edit?gid=775169775#gid=775169775&range=A"&MATCH(E19,Controle!E:E,0),"Ir") -> #N/A | G19: =COUNTIF(Controle!E:E,CONCAT("=",E19)) -> 1214 | H19: =SUMIFS(Controle!G:G,Controle!E:E,CONCAT("=",$E19),Controle!H:H,"<>0") -> 0 | I19: =SUMIFS(Controle!G:G,Controle!E:E,CONCAT("=",$E19),Controle!H:H,"=0") -> 0 | J19: =SUMIFS(Controle!G:G,Controle!E:E,CONCAT("=",$E19)) -> 0 | R19: =SUMIFS(Controle!G:G,Controle!A:A,CONCAT("=",$Q19),Controle!H:H,"<>0") -> 0 | S19: =SUMIFS(Controle!G:G,Controle!A:A,CONCAT("=",$Q19),Controle!H:H,"=0") -> 0 | T19: =SUMIFS(Controle!G:G,Controle!A:A,CONCAT("=",$Q19)) -> 0 | W19: =SUMIFS(Controle!G:G,Controle!A:A,CONCAT("=",$V19),Controle!H:H,"<>0") -> 0 | X19: =SUMIFS(Controle!G:G,Controle!A:A,CONCAT("=",$V19),Controle!H:H,"=0") -> 0 | Y19: =SUMIFS(Controle!G:G,Controle!A:A,CONCAT("=",$V19)) -> 0 | AE19: =SUMIFS(Controle!H:H,Controle!D:D,CONCAT("=",$AD19),Controle!I:I,"<>0") -> 0
A22: Usado | B22: Parcela | C22: Column 8 | D22: Vezes | E22: Pendentes | F22: Total Pendente | G22: Pagas | H22: Total Pago
A23: 45524 | B23: 1210.7 | D23: 10 | E23: =IF($A23,IF(IFERROR(DATEDIF($A23,CONCAT("01/",Mês_atual[[#HEADERS],[9/2026]]),"M"),0)<$D23,$D23-IFERROR(IFERROR(DATEDIF($A23,CONCAT("01/",Mês_atual[[#HEADERS],[9/2026]]),"M"),0),0),0),"") -> 0 | F23: =E23*B23 -> 0 | G23: =D23-E23 -> 10 | H23: =G23*B23 -> 12107 | L23: 1683.09
A24: 45558 | B24: 1250 | D24: 12 | E24: =IF($A24,IF(IFERROR(DATEDIF($A24,CONCAT("01/",Mês_atual[[#HEADERS],[9/2026]]),"M"),0)<$D24,$D24-IFERROR(IFERROR(DATEDIF($A24,CONCAT("01/",Mês_atual[[#HEADERS],[9/2026]]),"M"),0),0),0),"") -> 0 | F24: =E24*B24 -> 0 | G24: =D24-E24 -> 12 | H24: =G24*B24 -> 15000 | L24: 2965.46
A25: 45586 | B25: 1216.96 | D25: 10 | E25: =IF($A25,IF(IFERROR(DATEDIF($A25,CONCAT("01/",Mês_atual[[#HEADERS],[9/2026]]),"M"),0)<$D25,$D25-IFERROR(IFERROR(DATEDIF($A25,CONCAT("01/",Mês_atual[[#HEADERS],[9/2026]]),"M"),0),0),0),"") -> 0 | F25: =E25*B25 -> 0 | G25: =D25-E25 -> 10 | H25: =G25*B25 -> 12169.6 | L25: 500
A26: 45617 | B26: 1062.21 | D26: 10 | E26: =IF($A26,IF(IFERROR(DATEDIF($A26,CONCAT("01/",Mês_atual[[#HEADERS],[9/2026]]),"M"),0)<$D26,$D26-IFERROR(IFERROR(DATEDIF($A26,CONCAT("01/",Mês_atual[[#HEADERS],[9/2026]]),"M"),0),0),0),"") -> 0 | F26: =E26*B26 -> 0 | G26: =D26-E26 -> 10 | H26: =G26*B26 -> 10622.1 | L26: 160
A27: 45645 | B27: 1021.03 | D27: 10 | E27: =IF($A27,IF(IFERROR(DATEDIF($A27,CONCAT("01/",Mês_atual[[#HEADERS],[9/2026]]),"M"),0)<$D27,$D27-IFERROR(IFERROR(DATEDIF($A27,CONCAT("01/",Mês_atual[[#HEADERS],[9/2026]]),"M"),0),0),0),"") -> 0 | F27: =E27*B27 -> 0 | G27: =D27-E27 -> 10 | H27: =G27*B27 -> 10210.3 | L27: 300
A28: 45678 | B28: 583.95 | D28: 12 | E28: =IF($A28,IF(IFERROR(DATEDIF($A28,CONCAT("01/",Mês_atual[[#HEADERS],[9/2026]]),"M"),0)<$D28,$D28-IFERROR(IFERROR(DATEDIF($A28,CONCAT("01/",Mês_atual[[#HEADERS],[9/2026]]),"M"),0),0),0),"") -> 0 | F28: =E28*B28 -> 0 | G28: =D28-E28 -> 12 | H28: =G28*B28 -> 7007.4 | L28: =L23-(L24+L25+L26+L27) -> -2242.37
A29: 45708 | B29: 683.23 | D29: 12 | E29: =IF($A29,IF(IFERROR(DATEDIF($A29,CONCAT("01/",Mês_atual[[#HEADERS],[9/2026]]),"M"),0)<$D29,$D29-IFERROR(IFERROR(DATEDIF($A29,CONCAT("01/",Mês_atual[[#HEADERS],[9/2026]]),"M"),0),0),0),"") -> 0 | F29: =E29*B29 -> 0 | G29: =D29-E29 -> 12 | H29: =G29*B29 -> 8198.76
A30: 45740 | B30: 681.26 | D30: 10 | E30: =IF($A30,IF(IFERROR(DATEDIF($A30,CONCAT("01/",Mês_atual[[#HEADERS],[9/2026]]),"M"),0)<$D30,$D30-IFERROR(IFERROR(DATEDIF($A30,CONCAT("01/",Mês_atual[[#HEADERS],[9/2026]]),"M"),0),0),0),"") -> 0 | F30: =E30*B30 -> 0 | G30: =D30-E30 -> 10 | H30: =G30*B30 -> 6812.6
A31: 45771 | B31: 694.8 | D31: 10 | E31: =IF($A31,IF(IFERROR(DATEDIF($A31,CONCAT("01/",Mês_atual[[#HEADERS],[9/2026]]),"M"),0)<$D31,$D31-IFERROR(IFERROR(DATEDIF($A31,CONCAT("01/",Mês_atual[[#HEADERS],[9/2026]]),"M"),0),0),0),"") -> 0 | F31: =E31*B31 -> 0 | G31: =D31-E31 -> 10 | H31: =G31*B31 -> 6948
A32: 45800 | B32: 700 | D32: 10 | E32: =IF($A32,IF(IFERROR(DATEDIF($A32,CONCAT("01/",Mês_atual[[#HEADERS],[9/2026]]),"M"),0)<$D32,$D32-IFERROR(IFERROR(DATEDIF($A32,CONCAT("01/",Mês_atual[[#HEADERS],[9/2026]]),"M"),0),0),0),"") -> 0 | F32: =E32*B32 -> 0 | G32: =D32-E32 -> 10 | H32: =G32*B32 -> 7000
A33: 45832 | B33: 500 | D33: 10 | E33: =IF($A33,IF(IFERROR(DATEDIF($A33,CONCAT("01/",Mês_atual[[#HEADERS],[9/2026]]),"M"),0)<$D33,$D33-IFERROR(IFERROR(DATEDIF($A33,CONCAT("01/",Mês_atual[[#HEADERS],[9/2026]]),"M"),0),0),0),"") -> 0 | F33: =E33*B33 -> 0 | G33: =D33-E33 -> 10 | H33: =G33*B33 -> 5000
A34: 45861 | B34: 800 | D34: 10 | E34: =IF($A34,IF(IFERROR(DATEDIF($A34,CONCAT("01/",Mês_atual[[#HEADERS],[9/2026]]),"M"),0)<$D34,$D34-IFERROR(IFERROR(DATEDIF($A34,CONCAT("01/",Mês_atual[[#HEADERS],[9/2026]]),"M"),0),0),0),"") -> 0 | F34: =E34*B34 -> 0 | G34: =D34-E34 -> 10 | H34: =G34*B34 -> 8000
A35: 45892 | B35: 700 | D35: 12 | E35: =IF($A35,IF(IFERROR(DATEDIF($A35,CONCAT("01/",Mês_atual[[#HEADERS],[9/2026]]),"M"),0)<$D35,$D35-IFERROR(IFERROR(DATEDIF($A35,CONCAT("01/",Mês_atual[[#HEADERS],[9/2026]]),"M"),0),0),0),"") -> 0 | F35: =E35*B35 -> 0 | G35: =D35-E35 -> 12 | H35: =G35*B35 -> 8400
A36: 45923 | B36: 1000 | D36: 12 | E36: =IF($A36,IF(IFERROR(DATEDIF($A36,CONCAT("01/",Mês_atual[[#HEADERS],[9/2026]]),"M"),0)<$D36,$D36-IFERROR(IFERROR(DATEDIF($A36,CONCAT("01/",Mês_atual[[#HEADERS],[9/2026]]),"M"),0),0),0),"") -> 1 | F36: =E36*B36 -> 1000 | G36: =D36-E36 -> 11 | H36: =G36*B36 -> 11000
A37: 45952 | B37: 791.74 | D37: 12 | E37: =IF($A37,IF(IFERROR(DATEDIF($A37,CONCAT("01/",Mês_atual[[#HEADERS],[9/2026]]),"M"),0)<$D37,$D37-IFERROR(IFERROR(DATEDIF($A37,CONCAT("01/",Mês_atual[[#HEADERS],[9/2026]]),"M"),0),0),0),"") -> 2 | F37: =E37*B37 -> 1583.48 | G37: =D37-E37 -> 10 | H37: =G37*B37 -> 7917.4
B38: =SUMIF(Santander[Pendentes],">0",Santander[Parcela]) -> 1791.74 | F38: =SUM(F23:F37) -> 2583.48 | H38: =SUM(H23:H35) -> 117475.76
A41: Usado | B41: Parcela | C41: Column 8 | D41: Vezes | E41: Pendentes | F41: Total Pendente | G41: Pagas | H41: Total Pago
A42: 45952 | B42: 250 | D42: 12 | E42: =IF($A42,IF(IFERROR(DATEDIF($A42,CONCAT("01/",Mês_atual[[#HEADERS],[9/2026]]),"M"),0)<$D42,$D42-IFERROR(DATEDIF($A42,CONCAT("01/",Mês_atual[[#HEADERS],[9/2026]]),"M"),0),0),"") -> 2 | F42: =E42*B42 -> 500 | G42: =D42-E42 -> 10 | H42: =G42*B42 -> 2500
A43: 45885 | B43: 300 | D43: 10 | E43: =IF($A43,IF(IFERROR(DATEDIF($A43,CONCAT("01/",Mês_atual[[#HEADERS],[9/2026]]),"M"),0)<$D43,$D43-IFERROR(DATEDIF($A43,CONCAT("01/",Mês_atual[[#HEADERS],[9/2026]]),"M"),0),0),"") -> 0 | F43: =E43*B43 -> 0 | G43: =D43-E43 -> 10 | H43: =G43*B43 -> 3000
A44: 45771 | B44: 400 | D44: 5 | E44: =IF($A44,IF(IFERROR(DATEDIF($A44,CONCAT("01/",Mês_atual[[#HEADERS],[9/2026]]),"M"),0)<$D44,$D44-IFERROR(DATEDIF($A44,CONCAT("01/",Mês_atual[[#HEADERS],[9/2026]]),"M"),0),0),"") -> 0 | F44: =E44*B44 -> 0 | G44: =D44-E44 -> 5 | H44: =G44*B44 -> 2000
...

Sheet Controle
A1: Conta | B1: Local | C1: Tipo | D1: Categoria | E1: Vencimento | F1: Mês | G1: Valor | H1: Valor Pago | I1: Data Pagamento | J1: Coluna 2 | K1: Coluna 3 | L1: Coluna 4 | M1: Coluna 5 | N1: Coluna 6 | O1: Coluna 7 | P1: Coluna 8 | Q1: Coluna 9 | R1: Coluna 10 | S1: Coluna 11 | T1: Coluna 12 | U1: Coluna 13 | V1: Coluna 14 | W1: Coluna 15 | X1: Coluna 16 | Y1: Coluna 17 | Z1: Coluna 18 | AA1: Coluna 19 | AB1: Coluna 20 | AC1: Coluna 21 | AD1: Coluna 22
A2: Ademicon | B2: Casa | C2: Dívida | D2: Investimento | E2: 45001 | F2: =IF($E2,CONCATENATE(MONTH(E2),"/",YEAR(E2)),"") -> 3/2023 | G2: 649.6 | H2: =IF(I2,G2,0) -> 649.6 | I2: 45001
A3: Ademicon | B3: Casa | C3: Dívida | D3: Investimento | E3: 45024 | F3: =IF($E3,CONCATENATE(MONTH(E3),"/",YEAR(E3)),"") -> 4/2023 | G3: 649.6 | H3: =IF(I3,G3,0) -> 649.6 | I3: 45024
A4: Ademicon | B4: Casa | C4: Dívida | D4: Investimento | E4: 45054 | F4: =IF($E4,CONCATENATE(MONTH(E4),"/",YEAR(E4)),"") -> 5/2023 | G4: 649.6 | H4: =IF(I4,G4,0) -> 649.6 | I4: 45054
A5: Ademicon | B5: Casa | C5: Dívida | D5: Investimento | E5: 45085 | F5: =IF($E5,CONCATENATE(MONTH(E5),"/",YEAR(E5)),"") -> 6/2023 | G5: 649.6 | H5: =IF(I5,G5,0) -> 649.6 | I5: 45085
A6: Ademicon | B6: Casa | C6: Dívida | D6: Investimento | E6: 45115 | F6: =IF($E6,CONCATENATE(MONTH(E6),"/",YEAR(E6)),"") -> 7/2023 | G6: 649.6 | H6: =IF(I6,G6,0) -> 649.6 | I6: 45115
A7: Ademicon | B7: Casa | C7: Dívida | D7: Investimento | E7: 45146 | F7: =IF($E7,CONCATENATE(MONTH(E7),"/",YEAR(E7)),"") -> 8/2023 | G7: 649.6 | H7: =IF(I7,G7,0) -> 649.6 | I7: 45146
A8: Ademicon | B8: Casa | C8: Dívida | D8: Investimento | E8: 45177 | F8: =IF($E8,CONCATENATE(MONTH(E8),"/",YEAR(E8)),"") -> 9/2023 | G8: 649.6 | H8: =IF(I8,G8,0) -> 649.6 | I8: 45177
A9: Ademicon | B9: Casa | C9: Dívida | D9: Investimento | E9: 45207 | F9: =IF($E9,CONCATENATE(MONTH(E9),"/",YEAR(E9)),"") -> 10/2023 | G9: 649.6 | H9: =IF(I9,G9,0) -> 649.6 | I9: 45207
A10: Ademicon | B10: Casa | C10: Dívida | D10: Investimento | E10: 45238 | F10: =IF($E10,CONCATENATE(MONTH(E10),"/",YEAR(E10)),"") -> 11/2023 | G10: 649.6 | H10: =IF(I10,G10,0) -> 649.6 | I10: 45238
A11: Ademicon | B11: Casa | C11: Dívida | D11: Investimento | E11: 45268 | F11: =IF($E11,CONCATENATE(MONTH(E11),"/",YEAR(E11)),"") -> 12/2023 | G11: 649.6 | H11: =IF(I11,G11,0) -> 649.6 | I11: 45268
A12: Ademicon | B12: Casa | C12: Dívida | D12: Investimento | E12: 45299 | F12: =IF($E12,CONCATENATE(MONTH(E12),"/",YEAR(E12)),"") -> 1/2024 | G12: 666.95 | H12: =IF(I12,G12,0) -> 666.95 | I12: 45299
A13: Ademicon | B13: Casa | C13: Dívida | D13: Investimento | E13: 45330 | F13: =IF($E13,CONCATENATE(MONTH(E13),"/",YEAR(E13)),"") -> 2/2024 | G13: 666.95 | H13: =IF(I13,G13,0) -> 666.95 | I13: 45330
... A44: CC Santander | B44: Loja | C44: Dívida | D44: Investimento | E44: 45422 | F44: =IF($E44,CONCATENATE(MONTH(E44),"/",YEAR(E44)),"") -> 5/2024 | G44: 3236.86 | H44: =IF(I44,G44,0) -> 3236.86 | I44: 45422
A45: TIM | C45: Variavel | D45: Telefonia | E45: 45422 | F45: =IF($E45,CONCATENATE(MONTH(E45),"/",YEAR(E45)),"") -> 5/2024 | G45: 96.99 | H45: =IF(I45,G45,0) -> 96.99 | I45: 45422
A46: TIM | C46: Variavel | D46: Telefonia | E46: 45422 | F46: =IF($E46,CONCATENATE(MONTH(E46),"/",YEAR(E46)),"") -> 5/2024 | G46: 46.99 | H46: =IF(I46,G46,0) -> 46.99 | I46: 45422
A47: CC Cresol | C47: Dívida | D47: Investimento | E47: 45423 | F47: =IF($E47,CONCATENATE(MONTH(E47),"/",YEAR(E47)),"") -> 5/2024 | G47: 64.9 | H47: =IF(I47,G47,0) -> 64.9 | I47: 45423
A48: Pampasul | C48: Fornecedor | D48: Investimento | E48: 45427 | F48: =IF($E48,CONCATENATE(MONTH(E48),"/",YEAR(E48)),"") -> 5/2024 | G48: 936.28 | H48: =IF(I48,G48,0) -> 936.28 | I48: 45427
A49: Pampasul | C49: Fornecedor | D49: Investimento | E49: 45429 | F49: =IF($E49,CONCATENATE(MONTH(E49),"/",YEAR(E49)),"") -> 5/2024 | G49: 949.28 | H49: =IF(I49,G49,0) -> 949.28 | I49: 45429
A50: MEI | B50: GIS | C50: Variavel | D50: Imposto | E50: 45432 | F50: =IF($E50,CONCATENATE(MONTH(E50),"/",YEAR(E50)),"") -> 5/2024 | G50: 71.6 | H50: =IF(I50,G50,0) -> 71.6 | I50: 45432
A51: Botinas | C51: Fornecedor | D51: Investimento | E51: 45438 | F51: =IF($E51,CONCATENATE(MONTH(E51),"/",YEAR(E51)),"") -> 5/2024 | G51: 1000 | H51: =IF(I51,G51,0) -> 1000 | I51: 45438
A52: Sokolowski | C52: Fornecedor | D52: Investimento | E52: 45442 | F52: =IF($E52,CONCATENATE(MONTH(E52),"/",YEAR(E52)),"") -> 5/2024 | G52: 207.27 | H52: =IF(I52,G52,0) -> 207.27 | I52: 45442
A53: Copel | C53: Variavel | D53: Luz | E53: 45445 | F53: =IF($E53,CONCATENATE(MONTH(E53),"/",YEAR(E53)),"") -> 6/2024 | G53: 38.67 | H53: =IF(I53,G53,0) -> 38.67 | I53: 45445
A54: Ciarin | C54: Fornecedor | D54: Investimento | E54: 45450 | F54: =IF($E54,CONCATENATE(MONTH(E54),"/",YEAR(E54)),"") -> 6/2024 | G54: 292.61 | H54: =IF(I54,G54,0) -> 292.61 | I54: 45450
A55: Qualitchê | C55: Fornecedor | D55: Investimento | E55: 45451 | F55: =IF($E55,CONCATENATE(MONTH(E55),"/",YEAR(E55)),"") -> 6/2024 | G55: 881 | H55: =IF(I55,G55,0) -> 881 | I55: 45451
A56: CC Nubank | B56: Vinicius | C56: Dívida | D56: Investimento | E56: 45451 | F56: =IF($E56,CONCATENATE(MONTH(E56),"/",YEAR(E56)),"") -> 6/2024 | G56: 2294.92 | H56: =IF(I56,G56,0) -> 2294.92 | I56: 45451
A57: Sanepar | B57: Casa | C57: Variavel | D57: Água | E57: 45451 | F57: =IF($E57,CONCATENATE(MONTH(E57),"/",YEAR(E57)),"") -> 6/2024 | G57: 49.16 | H57: =IF(I57,G57,0) -> 49.16 | I57: 45451
A58: Ademicon | B58: Casa | C58: Dívida | D58: Investimento | E58: 45451 | F58: =IF($E58,CONCATENATE(MONTH(E58),"/",YEAR(E58)),"") -> 6/2024 | G58: 666.95 | H58: =IF(I58,G58,0) -> 666.95 | I58: 45451
A59: Aluguel | C59: Variavel | D59: Locação | E59: 45453 | F59: =IF($E59,CONCATENATE(MONTH(E59),"/",YEAR(E59)),"") -> 6/2024 | G59: 1000 | H59: =IF(I59,G59,0) -> 1000 | I59: 45453
A60: Meganet | C60: Variavel | D60: Internet | E60: 45453 | F60: =IF($E60,CONCATENATE(MONTH(E60),"/",YEAR(E60)),"") -> 6/2024 | G60: 129.9 | H60: =IF(I60,G60,0) -> 129.9 | I60: 45453
A61: Meganet | C61: Variavel | D61: Internet | E61: 45453 | F61: =IF($E61,CONCATENATE(MONTH(E61),"/",YEAR(E61)),"") -> 6/2024 | G61: 99.9 | H61: =IF(I61,G61,0) -> 99.9 | I61: 45453
A62: Sanepar | B62: Loja | C62: Variavel | D62: Água | E62: 45453 | F62: =IF($E62,CONCATENATE(MONTH(E62),"/",YEAR(E62)),"") -> 6/2024 | G62: 97.24 | H62: =IF(I62,G62,0) -> 97.24 | I62: 45453
A63: CC Santander | C63: Dívida | D63: Investimento | E63: 45453 | F63: =IF($E63,CONCATENATE(MONTH(E63),"/",YEAR(E63)),"") -> 6/2024 | G63: 10569.03 | H63: =IF(I63,G63,0) -> 10569.03 | I63: 45453
A64: Copel | C64: Variavel | D64: Luz | E64: 45453 | F64: =IF($E64,CONCATENATE(MONTH(E64),"/",YEAR(E64)),"") -> 6/2024 | G64: 143.41 | H64: =IF(I64,G64,0) -> 143.41 | I64: 45453
A65: TIM | C65: Variavel | D65: Telefonia | E65: 45453 | F65: =IF($E65,CONCATENATE(MONTH(E65),"/",YEAR(E65)),"") -> 6/2024 | G65: 96.99 | H65: =IF(I65,G65,0) -> 96.99 | I65: 45453
A66: TIM | C66: Variavel | D66: Telefonia | E66: 45453 | F66: =IF($E66,CONCATENATE(MONTH(E66),"/",YEAR(E66)),"") -> 6/2024 | G66: 49.99 | H66: =IF(I66,G66,0) -> 49.99 | I66: 45453
A67: CC Cresol | C67: Dívida | D67: Investimento | E67: 45454 | F67: =IF($E67,CONCATENATE(MONTH(E67),"/",YEAR(E67)),"") -> 6/2024 | G67: 339.95 | H67: =IF(I67,G67,0) -> 339.95 | I67: 45454
A68: Pampasul | C68: Fornecedor | D68: Investimento | E68: 45457 | F68: =IF($E68,CONCATENATE(MONTH(E68),"/",YEAR(E68)),"") -> 6/2024 | G68: 932.27 | H68: =IF(I68,G68,0) -> 932.27 | I68: 45457
A69: Empréstimo Cresol | C69: Dívida | D69: Dívida | E69: 45458 | F69: =IF($E69,CONCATENATE(MONTH(E69),"/",YEAR(E69)),"") -> 6/2024 | G69: 1015.63 | H69: =IF(I69,G69,0) -> 1015.63 | I69: 45458
A70: Pampasul | C70: Fornecedor | D70: Investimento | E70: 45460 | F70: =IF($E70,CONCATENATE(MONTH(E70),"/",YEAR(E70)),"") -> 6/2024 | G70: 949.28 | H70: =IF(I70,G70,0) -> 949.28 | I70: 45460
...

Sheet Custo marcas
A1: Sacudido's | B1: =IFERROR(__xludf.DUMMYFUNCTION("IMPORTRANGE(""https://docs.google.com/spreadsheets/d/1v7LYSfrIwyA0rrnvpZP1xdP32gJSacmF2axgu2Ii5X8/edit?gid=1175560505#gid=1175560505"", ""'Inventário de Estoque'!L1:L1"")"),"#REF!") -> #REF! | C1: =B1*2 -> #REF!
A2: Pé na estrada | B2: =IFERROR(__xludf.DUMMYFUNCTION("IMPORTRANGE(""https://docs.google.com/spreadsheets/d/1uN_smXhDQT14ctPzciDbxqtaVORBXQaa6NUJzIEWpkQ/edit?gid=1549833940#gid=1549833940"", ""'Inventário de Estoque'!L1:L1"")"),"#REF!") -> #REF! | C2: =B2*2 -> #REF!
A3: Kappell | B3: =IFERROR(__xludf.DUMMYFUNCTION("IMPORTRANGE(""https://docs.google.com/spreadsheets/d/14YKVMFWnonTFFbLI75yjFymR53okEYkIzGcO5nS5LAc/edit?gid=361854317#gid=361854317"", ""'Inventário de Estoque'!L1:L1"")"),"#REF!") -> #REF! | C3: =B3*2 -> #REF!
A4: Vuollo | B4: =IFERROR(__xludf.DUMMYFUNCTION("IMPORTRANGE(""https://docs.google.com/spreadsheets/d/1pmhD74GsPoEZa3BZjLOMYJCrvJ2C5C-973gDnuBLH38/edit?gid=1758114367#gid=1758114367"", ""'Inventário de Estoque'!L1:L1"")"),"#REF!") -> #REF! | C4: =B4*2 -> #REF!
A5: Cla-cle | B5: =IFERROR(__xludf.DUMMYFUNCTION("IMPORTRANGE(""https://docs.google.com/spreadsheets/d/1N4I4KPDNkpitO0xZkJy6QHL0g37U0pnjLh8cLhUBDCI/edit?gid=542127081#gid=542127081"", ""'Inventário de Estoque'!L1:L1"")"),"#REF!") -> #REF! | C5: =B5*2 -> #REF!
A6: Qualitche | B6: =IFERROR(__xludf.DUMMYFUNCTION("IMPORTRANGE(""https://docs.google.com/spreadsheets/d/1JzQUhonU7d5R2Bilb2wA3sQmgwsx4I8ooBONFTWXf5w/edit?gid=1912606609#gid=1912606609"", ""'Inventário de Estoque'!L1:L1"")"),"#REF!") -> #REF! | C6: =B6*2 -> #REF!
A7: Pura Raça | B7: =IFERROR(__xludf.DUMMYFUNCTION("IMPORTRANGE(""https://docs.google.com/spreadsheets/d/11tYWoSGCdybRgk8GnZXXdtK4ZyQgLqzQskHtbsRJo6o/edit?gid=438354460#gid=438354460"", ""'Inventário de Estoque'!L1:L1"")"),"#REF!") -> #REF! | C7: =B7*2 -> #REF!
A8: Texanus | B8: =IFERROR(__xludf.DUMMYFUNCTION("IMPORTRANGE(""https://docs.google.com/spreadsheets/d/1odqGiEiMPrDWQr7T-scvjbEUjGIaOzTLkTwiIstwuiQ/edit?gid=1559247720#gid=1559247720"", ""'Inventário de Estoque'!L1:L1"")"),"#REF!") -> #REF! | C8: =B8*2 -> #REF!
A9: Mula Rosa | B9: =IFERROR(__xludf.DUMMYFUNCTION("IMPORTRANGE(""https://docs.google.com/spreadsheets/d/174b3LO_c3aR-IS8A91CUJ91S4FGemVHoCWLRm6SrHCA/edit?gid=710208362#gid=710208362"", ""'Inventário de Estoque'!L1:L1"")"),"#REF!") -> #REF! | C9: =B9*2 -> #REF!
A10: Montana | B10: =IFERROR(__xludf.DUMMYFUNCTION("IMPORTRANGE(""https://docs.google.com/spreadsheets/d/19S80tP4e7P3RV7SnlzRsH4UArEa_W3Od4gNSTdQ2588/edit?gid=1141953125#gid=1141953125"", ""'Inventário de Estoque'!L1:L1"")"),"#REF!") -> #REF! | C10: =B10*2 -> #REF!
A11: Cowgirl | B11: =IFERROR(__xludf.DUMMYFUNCTION("IMPORTRANGE(""https://docs.google.com/spreadsheets/d/1KS-VNuujap8DkmofjUzSTISnc0w5ibmXSZcCp-9bVnM/edit?gid=840031567#gid=840031567"", ""'Inventário de Estoque'!L1:L1"")"),"#REF!") -> #REF! | C11: =B11*2 -> #REF!
A12: Pampa Sul | B12: =IFERROR(__xludf.DUMMYFUNCTION("IMPORTRANGE(""https://docs.google.com/spreadsheets/d/1cUmN9IpPQGidGW1nT26FqsPC6lhljQ4IQoWxN1JYb-M/edit?gid=1485932453#gid=1485932453"", ""'Inventário de Estoque'!L1:L1"")"),"#REF!") -> #REF! | C12: =B12*2 -> #REF!
A13: Made in Mato | B13: =IFERROR(__xludf.DUMMYFUNCTION("IMPORTRANGE(""https://docs.google.com/spreadsheets/d/1tQ_GjBt1INNPF4y9dzUtDUQzkToDyIRhe7xW643Lg4U/edit?gid=522286354#gid=522286354"", ""'Inventário de Estoque'!L1:L1"")"),"#REF!") -> #REF! | C13: =B13*2 -> #REF!
A14: Master Couros | B14: =IFERROR(__xludf.DUMMYFUNCTION("IMPORTRANGE(""https://docs.google.com/spreadsheets/d/1NpM0m06KsngqrSI2pwuxFYdXNW5e9CHK3qo5zEe1Orw/edit?gid=1822251035#gid=1822251035"", ""'Inventário de Estoque'!L1:L1"")"),"#REF!") -> #REF! | C14: =B14*2 -> #REF!
A15: Ciarin | B15: =IFERROR(__xludf.DUMMYFUNCTION("IMPORTRANGE(""https://docs.google.com/spreadsheets/d/1H6tg39SrJY6glzjKJBhoEb9Qiby_AbRZ8VDk4dKiTwk/edit?gid=1190618551#gid=1190618551"", ""'Inventário de Estoque'!L1:L1"")"),"#REF!") -> #REF! | C15: =B15*2 -> #REF!
A16: Selaria Pinheiro | B16: =IFERROR(__xludf.DUMMYFUNCTION("IMPORTRANGE(""https://docs.google.com/spreadsheets/d/19zsLB6iRpAYilIVvaCoY4rghGNkx2P0LWbIrFfj5G5s/edit?gid=2043833364#gid=2043833364"", ""'Inventário de Estoque'!L1:L1"")"),"#REF!") -> #REF! | C16: =B16*2 -> #REF!
A17: Texas Farm | B17: =IFERROR(__xludf.DUMMYFUNCTION("IMPORTRANGE(""https://docs.google.com/spreadsheets/d/1ARsi6fbFT7P7rTCA6JfXQtcgJz5ItrMQoL9F9BR0L94/edit?gid=1532243408#gid=1532243408"", ""'Inventário de Estoque'!L1:L1"")"),"#REF!") -> #REF! | C17: =B17*2 -> #REF!
A18: Tordilho Negro | B18: =IFERROR(__xludf.DUMMYFUNCTION("IMPORTRANGE(""https://docs.google.com/spreadsheets/d/1URh45kCKLaAU0VNzdVEgjCHQRWCLmQ63ZaMuigU-vbI/edit?gid=681508335#gid=681508335"", ""'Inventário de Estoque'!L1:L1"")"),"#REF!") -> #REF! | C18: =B18*2 -> #REF!
A19: MOR | B19: =IFERROR(__xludf.DUMMYFUNCTION("IMPORTRANGE(""https://docs.google.com/spreadsheets/d/1NnlqBRsE-LBQKiHRCojuwoIGdfy6Vg5ECoqmWRzE95k/edit?gid=1106525878#gid=1106525878"", ""'Inventário de Estoque'!L1:L1"")"),"#REF!") -> #REF! | C19: =B19*2 -> #REF!
A20: Black | B20: =IFERROR(__xludf.DUMMYFUNCTION("IMPORTRANGE(""https://docs.google.com/spreadsheets/d/1VJqyIHZS1_V2zxoXXclSXb5haVQZbgWH_qVNkpA1SAY/edit?gid=1736627674#gid=1736627674"", ""'Inventário de Estoque'!L1:L1"")"),"#REF!") -> #REF! | C20: =B20*2 -> #REF!
B25: =SUM(B1:B24) -> #REF! | C25: =SUM(C1:C24) -> #REF!

Sheet Categorias
A1: Categorias de conta
A2: Selecione
A3: Dívida
A4: Luz
A5: Água
A6: Investimento
A7: Locação
A8: Telefonia
A9: Internet
A10: Imposto
A11: Seguro
A12: Combustivel
A13: Mercado

Sheet Calculadora de preço
A1: Valor do Produto | B1: 219 | D1: Tabela de tarifas Stone | F1: Parcela | G1: Á Receber | H1: Margem
A2: Valor Sugerido de venda | B2: =(($B$1*$B$3)) -> 438 | D2: Antecipação | E2: 2.6 | F2: - | G2: -
A3: Markup | B3: 2 | D3: Débito | E3: 1.81 | F3: =B2-(B2*(E3/100)) -> 430.0722 | G3: =$B$2-($B$2*($E3/100)) -> 430.0722 | H3: =$G3-$B$1 -> 211.0722 | M3: Projeção | N3: A vista | P3: A Prazo | Q3: Estoque | S3: Parcelas | T3: Valor | U3: A Prazo
A4: Margem de lucro | B4: =(($B$2-$B$1)/$B$2) -> 0.5 | D4: Crédito | E4: 2.87 | F4: =B2-(B2*(E4/100))-(B2*(E2/100)) -> 414.0414 | G4: =$B$2-($B$2*(($E4+$E$2)/100)) -> 414.0414 | H4: =$G4-$B$1 -> 195.0414 | J4: 89 | K4: 179.9 | L4: Blusa Sul de Minas | M4: =((($J4*$B$4)+($J4*#REF!))*100)/(100-$B$5) -> #REF! | N4: 135.9 | O4: =(N4*100)/K4 -> 75.541968 | P4: 149.9 | Q4: 24 | R4: =Q4*N4 -> 3261.6 | S4: 6 | T4: =(N4*1.2)/S4 -> 27.18 | U4: =S4*T4 -> 163.08
A5: Tarifa máxima | B5: 12.14 | D5: 2a 6x | E5: 3.34 | G5: =B2-((E5/100)*B2) -> 423.3708 | H5: =$G5-$B$1 -> 204.3708 | J5: 69 | K5: 169.9 | L5: Moletom Bem Campeiro - Infantil | M5: =((($J5*$B$4)+($J5*#REF!))*100)/(100-$B$5) -> #REF! | N5: 105.9 | O5: =(N5*100)/K5 -> 62.330783 | P5: 119.9 | Q5: 14 | R5: =Q5*N5 -> 1482.6 | S5: 6 | T5: =(N5*1.2)/S5 -> 21.18 | U5: =S5*T5 -> 127.08
D6: 2 | F6: =$G$5/$D6 -> 211.6854 | G6: =($F6-($F6*((1*$E$2)/100)))+($F6-($F6*((2*$E$2)/100))) -> 406.85934 | H6: =$G6-$B$1 -> 187.85934 | J6: 89 | K6: 209.9 | L6: Moletom Bem Campeiro - Adulto | M6: =((($J6*$B$4)+($J6*#REF!))*100)/(100-$B$5) -> #REF! | N6: 135.9 | O6: =(N6*100)/K6 -> 64.745117 | P6: 149.9 | Q6: 25 | R6: =Q6*N6 -> 3397.5 | S6: 6 | T6: =(N6*1.2)/S6 -> 27.18 | U6: =S6*T6 -> 163.08
D7: 3 | F7: =$G$5/$D7 -> 141.1236 | G7: =($F7-($F7*((1*$E$2)/100)))+($F7-($F7*((2*$E$2)/100)))+($F7-($F7*((3*$E$2)/100))) -> 401.35552 | H7: =$G7-$B$1 -> 182.35552 | J7: 116.5 | K7: 239.9 | L7: Moletom Cowgirl | M7: =((($J7*$B$4)+($J7*#REF!))*100)/(100-$B$5) -> #REF! | N7: 175.9 | O7: =(N7*100)/K7 -> 73.322218 | P7: 195.9 | Q7: 8 | R7: =Q7*N7 -> 1407.2 | S7: 6 | T7: =(N7*1.2)/S7 -> 35.18 | U7: =S7*T7 -> 211.08
D8: 4 | F8: =$G$5/$D8 -> 105.8427 | G8: =($F8-($F8*((1*$E$2)/100)))+($F8-($F8*((2*$E$2)/100)))+($F8-($F8*((3*$E$2)/100)))+($F8-($F8*((4*$E$2)/100))) -> 395.8517 | H8: =$G8-$B$1 -> 176.8517 | J8: 36 | K8: 79.9 | L8: Corta Vento - Eklética | M8: =((($J8*$B$4)+($J8*#REF!))*100)/(100-$B$5) -> #REF! | N8: 59.9 | O8: =(N8*100)/K8 -> 74.968711 | P8: 65.9 | Q8: 26 | R8: =Q8*N8 -> 1557.4 | S8: 6 | T8: =(N8*1.2)/S8 -> 11.98 | U8: =S8*T8 -> 71.88
D9: 5 | F9: =$G$5/$D9 -> 84.67416 | G9: =($F9-($F9*((1*$E$2)/100)))+($F9-($F9*((2*$E$2)/100)))+($F9-($F9*((3*$E$2)/100)))+($F9-($F9*((4*$E$2)/100)))+($F9-($F9*((5*$E$2)/100))) -> 390.34788 | H9: =$G9-$B$1 -> 171.34788 | J9: 54 | K9: 129.9 | L9: Manga Longa Bem Campeiro - Adulto | M9: =((($J9*$B$4)+($J9*#REF!))*100)/(100-$B$5) -> #REF! | N9: 85.9 | O9: =(N9*100)/K9 -> 66.127791 | P9: 95.9 | Q9: 28 | R9: =Q9*N9 -> 2405.2 | S9: 6 | T9: =(N9*1.2)/S9 -> 17.18 | U9: =S9*T9 -> 103.08
D10: 6 | F10: =$G$5/$D10 -> 70.5618 | G10: =($F10-($F10*((1*$E$2)/100)))+($F10-($F10*((2*$E$2)/100)))+($F10-($F10*((3*$E$2)/100)))+($F10-($F10*((4*$E$2)/100)))+($F10-($F10*((5*$E$2)/100)))+($F10-($F10*((6*$E$2)/100))) -> 384.84406 | H10: =$G10-$B$1 -> 165.84406 | J10: 44 | K10: 109.9 | L10: Manga Longa Bem Campeiro - Infantil | M10: =((($J10*$B$4)+($J10*#REF!))*100)/(100-$B$5) -> #REF! | N10: 69.9 | O10: =(N10*100)/K10 -> 63.603276 | P10: 79.9 | Q10: 18 | R10: =Q10*N10 -> 1258.2 | S10: 6 | T10: =(N10*1.2)/S10 -> 13.98 | U10: =S10*T10 -> 83.88
D11: Pix | E11: 0 | G11: =$B$2-($B$2*($E11/100)) -> 438 | H11: =$G11-$B$1 -> 219 | J11: 39.77 | K11: 99.9 | L11: Manga Longa - Country Kids - Infantil | M11: =((($J11*$B$4)+($J11*#REF!))*100)/(100-$B$5) -> #REF! | N11: 69.9 | O11: =(N11*100)/K11 -> 69.96997 | P11: 79.9 | Q11: 13 | R11: =Q11*N11 -> 908.7 | S11: 6 | T11: =(N11*1.2)/S11 -> 13.98 | U11: =S11*T11 -> 83.88
D12: Dinheiro | E12: 0 | G12: =$B$2-($B$2*($E12/100)) -> 438 | H12: =$G12-$B$1 -> 219 | J12: 43.48 | K12: 109.9 | L12: Manga Longa - Jopper Bulls - Adulto | M12: =((($J12*$B$4)+($J12*#REF!))*100)/(100-$B$5) -> #REF! | N12: 85.9 | O12: =(N12*100)/K12 -> 78.161965 | P12: 95.9 | Q12: 12 | R12: =Q12*N12 -> 1030.8 | S12: 6 | T12: =(N12*1.2)/S12 -> 17.18 | U12: =S12*T12 -> 103.08
J13: 43.48 | K13: 109.9 | L13: Manga Longa - Mula Rosa - Adulto | M13: =((($J13*$B$4)+($J13*#REF!))*100)/(100-$B$5) -> #REF! | N13: 85.9 | O13: =(N13*100)/K13 -> 78.161965 | P13: 95.9 | Q13: 13 | R13: =Q13*N13 -> 1116.7 | S13: 6 | T13: =(N13*1.2)/S13 -> 17.18 | U13: =S13*T13 -> 103.08
R15: =SUM(R4:R13) -> 17825.9

Sheet Tordilho Negro
A1: Produto | B1: Recebido | C1: Atual | D1: Custo | E1: Venda | F1: 45352 | H1: 45383 | J1: 45413 | L1: 45444 | N1: 45474 | P1: 45505 | R1: 45536 | T1: 45566 | V1: 45597 | X1: 45627
A2: Camisa Polo Adulto | B2: =8+11+14+13+4+11+2+3+7+10+16+13+3+8+10+5+8+12+17+13+13+17+12+9+6+10+5+9+13+18+11+10+9+15+6+6+11+17+13+10 -> 408 | C2: 383 | D2: 39.72 | E2: 89.9 | F2: 1 | G2: =F2*D2 -> 39.72 | H2: 10 | I2: =H2*D2 -> 397.2 | J2: 4 | K2: =J2*D2 -> 158.88 | L2: 9 | M2: =L2*D2 -> 357.48 | O2: =N2*D2 -> 0 | Q2: =P2*F2 -> 0 | S2: =R2*H2 -> 0 | U2: =T2*J2 -> 0 | W2: =V2*L2 -> 0 | Y2: =X2*N2 -> 0
A3: Camisa Polo Baby | B3: =3+4+2+5+5+4 -> 23 | C3: 22 | D3: 25.03 | E3: 59.9 | F3: 1 | G3: =F3*D3 -> 25.03 | I3: =H3*D3 -> 0 | K3: =J3*D3 -> 0 | M3: =L3*D3 -> 0 | O3: =N3*D3 -> 0 | Q3: =P3*F3 -> 0 | S3: =R3*H3 -> 0 | U3: =T3*J3 -> 0 | W3: =V3*L3 -> 0 | Y3: =X3*N3 -> 0
A4: Camisa Polo Infantil | B4: =4+5+5+3+4+3+4+5+4 -> 37 | C4: 32 | D4: 29.08 | E4: 69.9 | F4: 1 | G4: =F4*D4 -> 29.08 | H4: 2 | I4: =H4*D4 -> 58.16 | K4: =J4*D4 -> 0 | L4: 1 | M4: =L4*D4 -> 29.08 | O4: =N4*D4 -> 0 | Q4: =P4*F4 -> 0 | S4: =R4*H4 -> 0 | U4: =T4*J4 -> 0 | W4: =V4*L4 -> 0 | Y4: =X4*N4 -> 0
A5: Ceva Mate | B5: 213 | C5: 210 | D5: 4.55 | E5: 15 | F5: 3 | G5: =F5*D5 -> 13.65 | I5: =H5*D5 -> 0 | K5: =J5*D5 -> 0 | M5: =L5*D5 -> 0 | O5: =N5*D5 -> 0 | Q5: =P5*F5 -> 0 | S5: =R5*H5 -> 0 | U5: =T5*J5 -> 0 | W5: =V5*L5 -> 0 | Y5: =X5*N5 -> 0
A6: Chinelo Campeiro | B6: 26 | C6: 25 | D6: 34.74 | E6: 69.9 | G6: =F6*D6 -> 0 | H6: 1 | I6: =H6*D6 -> 34.74 | K6: =J6*D6 -> 0 | M6: =L6*D6 -> 0 | O6: =N6*D6 -> 0 | Q6: =P6*F6 -> 0 | S6: =R6*H6 -> 0 | U6: =T6*J6 -> 0 | W6: =V6*L6 -> 0 | Y6: =X6*N6 -> 0
A7: Cuia c/ Bomba | B7: 15 | C7: 10 | D7: 34.97 | E7: 69.9 | F7: 1 | G7: =F7*D7 -> 34.97 | H7: 3 | I7: =H7*D7 -> 104.91 | J7: 1 | K7: =J7*D7 -> 34.97 | M7: =L7*D7 -> 0 | O7: =N7*D7 -> 0 | Q7: =P7*F7 -> 0 | S7: =R7*H7 -> 0 | U7: =T7*J7 -> 0 | W7: =V7*L7 -> 0 | Y7: =X7*N7 -> 0
A8: Mateira | B8: 26 | C8: 26 | D8: 25 | E8: 79.9 | G8: =F8*D8 -> 0 | I8: =H8*D8 -> 0 | K8: =J8*D8 -> 0 | M8: =L8*D8 -> 0 | O8: =N8*D8 -> 0 | Q8: =P8*F8 -> 0 | S8: =R8*H8 -> 0 | U8: =T8*J8 -> 0 | W8: =V8*L8 -> 0 | Y8: =X8*N8 -> 0
B9: =SUM(B2:B8) -> 748 | C9: =SUM(C2:C8) -> 708 | F9: =SUM(F2:F8) -> 7 | G9: =SUM(G2:G8) -> 142.45 | H9: =SUM(H2:H8) -> 16 | I9: =SUM(I2:I8) -> 595.01 | J9: =SUM(J2:J8) -> 5 | K9: =SUM(K2:K8) -> 193.85 | L9: =SUM(L2:L8) -> 10 | M9: =SUM(M2:M8) -> 386.56 | ... Y9: =SUM(Y2:Y8) -> 0
